tests/64_threads/sample_14.in
64
o
63 S 101 1 135 967
26 B 105 5 168 810
63 S 106 9 156 272
7 B 107 3 114 491
27 B 108 3 185 156
28 B 109 9 153 395
27 B 111 1 162 625
8 S 113 9 157 760
26 B 114 5 124 475
14 S 115 6 165 868
10 S 117 0 177 283
63 B 118 5 149 124
46 S 119 0 111 138
38 S 121 0 146 205
25 S 122 2 107 864
4 B 124 9 192 118
0 B 125 1 138 48
13 B 126 6 193 923
38 B 127 0 104 191
45 B 128 5 134 943
62 S 129 0 162 309
29 S 130 7 155 70
51 B 131 9 170 1000
28 S 132 1 120 414
9 S 133 0 103 727
55 B 134 8 144 423
26 C 105
42 B 136 9 137 118
52 B 137 0 152 926
51 B 140 7 136 473
63 C 101
11 B 142 3 136 38
27 C 111
60 B 145 8 164 255
30 B 146 0 153 298
45 S 147 3 173 129
39 S 150 5 190 89
46 S 152 8 101 793
39 C 150
32 B 155 0 115 329
58 S 156 0 126 316
12 S 157 0 107 397
60 S 158 7 129 196
28 B 159 6 176 929
34 S 160 2 132 222
12 S 161 9 111 490
18 S 164 4 139 70
2 B 165 8 132 203
21 S 166 8 156 217
37 B 167 6 189 671
57 S 168 4 130 328
60 C 145
42 B 171 2 188 749
3 B 172 8 158 236
40 B 174 7 159 180
0 C 125
38 C 127
57 C 168
36 B 178 3 166 213
56 B 179 7 185 747
62 S 180 3 146 298
51 C 131
31 S 182 0 160 458
25 B 183 9 177 773
33 B 184 8 186 431
4 C 124
51 S 186 0 171 519
23 B 188 4 105 157
18 S 189 9 136 306
62 B 191 5 151 41
56 C 179
59 B 194 8 161 33
36 B 196 2 197 422
23 B 197 2 115 244
2 B 198 3 182 200
59 C 194
52 S 200 0 193 963
35 B 202 8 124 179
23 S 203 3 164 364
62 C 129
6 S 205 0 101 401
35 B 206 9 191 580
27 S 207 5 128 580
54 B 208 8 194 213
10 B 210 8 139 343
19 B 211 9 126 459
4 C 124
10 B 213 3 194 485
34 C 160
33 C 184
6 B 216 9 190 254
4 S 217 7 122 878
25 C 122
46 C 152
42 S 221 5 125 970
51 B 222 6 136 579
56 B 223 3 124 77
17 S 224 6 129 710
7 B 225 5 141 124
31 B 226 8 107 223
62 C 191
44 B 228 5 114 196
49 B 229 3 133 258
58 S 231 5 166 823
40 S 232 0 198 966
40 S 233 0 147 984
10 B 234 5 180 38
39 S 235 7 169 916
40 B 236 1 167 546
35 S 237 6 145 663
52 B 238 6 106 27
31 C 226
10 B 240 6 100 818
6 B 241 9 191 906
39 C 150
56 S 243 1 122 482
18 C 189
54 S 245 2 117 234
33 C 184
6 S 247 9 169 897
17 S 248 6 175 253
13 S 249 7 135 676
37 B 250 4 133 650
36 B 251 2 139 761
45 B 252 0 108 543
9 C 133
58 C 156
4 S 256 7 117 308
57 S 257 1 173 263
42 C 221
52 C 137
44 B 260 0 133 14
56 S 261 5 175 423
21 C 166
51 C 131
43 B 264 1 139 767
51 S 265 7 133 652
35 C 237
62 S 267 8 106 50
46 C 152
29 C 130
46 B 270 9 187 459
45 S 271 1 110 555
31 S 272 5 134 783
50 B 273 8 124 773
48 B 274 6 169 512
27 S 275 1 172 827
36 B 276 6 143 847
27 S 277 5 135 97
42 C 136
33 C 184
49 B 280 2 119 131
0 S 281 5 129 933
54 S 282 0 154 175
49 C 280
30 B 284 0 179 987
21 B 285 4 147 281
13 B 286 8 152 606
44 S 287 8 194 380
36 S 288 1 191 956
60 S 289 4 137 218
16 S 290 4 139 404
28 B 291 3 165 545
11 C 142
59 C 194
26 S 294 8 187 692
48 B 295 0 137 948
28 B 296 5 157 417
44 C 260
22 B 298 3 149 644
42 S 299 7 115 910
59 S 300 6 184 801
4 C 256
49 B 302 0 193 15
38 C 121
15 S 304 3 167 249
37 B 305 1 174 731
9 B 306 2 179 621
19 C 211
29 C 130
5 S 310 6 144 745
62 S 311 8 122 97
2 B 312 8 187 781
44 C 287
43 C 264
14 S 315 6 111 814
52 B 316 8 199 344
28 S 317 6 103 276
15 B 318 3 166 504
40 C 232
63 B 320 6 197 43
8 C 113
63 B 322 4 127 621
56 C 223
23 B 324 6 165 486
14 S 325 5 148 625
58 S 326 4 126 224
57 C 168
49 S 329 5 106 258
51 B 330 7 119 170
15 B 331 3 104 578
18 C 164
39 S 333 8 189 635
51 S 334 7 109 649
28 S 335 6 159 233
26 C 114
52 B 337 5 163 238
29 B 338 7 120 352
14 B 339 3 108 727
39 S 340 4 132 43
31 B 341 3 100 920
15 S 342 6 107 353
6 S 343 6 148 658
43 S 344 4 111 728
62 S 345 8 174 122
2 B 346 0 149 192
10 S 347 1 137 152
50 C 273
33 S 349 9 159 806
18 B 350 6 137 810
46 B 351 9 117 794
59 B 352 5 133 72
59 B 353 6 184 456
62 B 354 4 181 14
31 C 272
62 B 356 6 159 497
63 B 358 9 144 605
15 S 359 1 105 336
16 S 360 8 157 123
25 B 361 0 185 931
8 B 362 4 194 219
6 B 363 1 137 363
60 C 158
29 B 365 0 136 69
60 C 289
24 S 367 7 132 886
21 C 166
30 S 369 6 176 840
48 B 370 1 141 597
28 C 291
52 S 372 1 133 246
43 S 373 8 194 377
18 S 375 4 185 444
50 S 376 4 147 567
56 C 179
29 S 378 0 191 907
35 C 202
34 S 380 5 127 574
11 B 381 4 186 473
21 C 166
3 S 383 7 100 202
47 B 384 1 179 416
40 C 236
7 C 225
45 B 387 6 136 102
51 B 388 8 128 13
49 C 229
30 S 390 6 139 948
63 S 391 4 137 978
13 C 286
26 B 393 8 144 991
45 B 394 1 132 342
62 S 395 1 136 473
36 B 396 1 122 177
57 B 397 7 138 157
42 B 398 8 118 652
36 B 399 3 160 819
52 C 372
56 B 401 8 173 334
39 B 402 4 127 297
57 C 397
6 C 247
15 S 405 8 159 874
16 S 406 5 137 626
24 S 407 2 180 622
51 B 408 1 137 436
16 S 409 3 160 423
0 S 410 4 145 834
49 C 280
21 S 413 9 136 189
34 B 414 6 186 543
33 S 415 5 150 130
38 S 416 5 177 150
38 B 417 9 177 269
2 B 418 1 114 31
37 S 419 4 117 852
4 C 124
6 B 421 2 169 435
36 C 399
24 C 367
60 S 424 1 146 622
59 B 425 5 118 922
30 B 426 7 120 764
47 C 384
5 C 310
12 S 429 9 200 933
10 C 210
35 S 431 6 154 925
49 C 229
0 C 281
43 C 373
2 S 435 3 139 672
21 S 436 0 106 724
29 S 437 6 114 339
3 S 438 7 128 516
41 B 439 0 161 380
57 B 440 9 122 321
19 B 441 0 170 799
60 B 442 1 119 290
60 C 145
53 S 444 6 138 346
28 S 445 7 179 525
18 C 375
31 B 447 8 162 216
33 S 448 7 171 433
41 C 439
53 C 444
5 C 310
60 B 452 6 121 260
12 B 453 2 169 707
11 S 454 9 128 416
3 C 172
27 C 108
25 S 457 0 138 555
58 S 458 0 109 115
21 B 459 4 119 175
8 B 460 7 162 491
27 C 207
38 C 121
46 B 463 8 126 554
58 S 464 8 133 745
31 S 465 2 149 809
52 C 316
11 S 467 4 157 615
42 S 468 3 105 195
59 B 469 4 189 129
62 B 470 8 181 42
43 S 471 1 140 845
10 C 347
25 B 473 4 186 349
34 S 474 8 158 94
40 B 475 7 149 476
10 S 476 1 144 104
40 B 477 7 141 511
52 S 478 6 146 901
63 S 479 0 110 661
33 B 480 5 106 797
47 B 481 1 125 554
58 C 458
7 C 225
55 B 484 7 161 366
35 S 485 1 195 471
54 B 486 4 189 293
43 B 487 5 176 209
16 S 488 3 136 163
47 S 489 3 156 231
48 C 370
7 C 225
34 B 492 9 116 364
44 C 287
49 S 494 7 194 143
50 B 495 8 190 770
41 B 496 5 146 916
53 B 497 9 172 516
37 S 498 5 143 550
1 B 499 5 159 350
28 S 500 6 173 642
5 C 310
52 B 502 1 188 956
30 B 503 3 154 116
46 B 504 2 152 348
38 S 505 1 148 800
30 S 506 5 104 85
53 B 507 6 172 458
0 S 508 5 156 889
5 C 310
38 B 510 6 188 60
13 S 511 9 150 420
58 C 231
12 C 429
56 S 514 0 110 739
15 B 515 2 187 494
38 B 516 5 181 26
30 S 517 6 172 82
39 S 518 6 133 979
35 B 519 4 136 616
14 B 520 0 176 650
20 S 521 6 181 688
50 S 522 8 120 190
3 B 523 6 195 862
34 C 492
22 C 298
31 C 465
38 C 510
47 B 528 9 123 26
25 B 529 3 138 38
27 C 111
22 B 531 9 129 792
20 C 521
55 B 533 0 106 131
5 B 534 6 168 535
50 S 535 4 189 245
62 S 536 2 189 546
42 B 537 7 134 350
43 B 538 1 113 872
15 B 539 8 175 689
3 C 438
8 C 460
17 C 248
34 C 414
8 S 544 7 173 679
17 C 224
62 S 546 3 108 644
7 B 547 2 160 621
33 B 548 5 178 252
50 C 376
41 C 496
18 S 551 0 105 700
62 C 345
28 C 445
0 B 554 6 177 310
58 B 555 4 194 984
23 S 556 3 198 638
7 B 557 3 180 329
30 C 426
58 C 156
8 S 560 9 133 762
2 B 561 9 157 128
42 C 468
1 S 563 0 105 856
26 C 294
9 S 565 2 157 421
33 B 566 8 141 914
15 B 567 4 112 689
9 C 565
41 S 569 8 115 55
57 B 570 4 148 680
23 S 571 5 182 496
27 B 572 4 103 931
15 S 573 4 160 114
30 S 574 8 110 347
3 S 575 4 178 77
22 S 576 7 147 642
1 B 577 1 179 771
26 B 578 3 166 700
1 B 579 5 142 20
44 S 580 4 103 805
4 B 581 5 133 512
6 B 582 8 119 278
16 S 583 5 149 994
61 S 584 8 135 798
23 S 585 7 190 348
4 C 256
45 S 587 6 106 96
62 C 180
22 S 589 9 179 565
43 S 590 8 111 707
63 C 118
63 B 592 3 194 527
35 B 593 1 199 342
38 S 594 0 115 919
33 B 595 4 106 484
49 B 596 2 116 771
16 B 597 2 147 660
62 B 598 6 134 414
44 S 599 0 132 242
19 S 600 6 134 834
58 B 601 0 172 741
63 B 602 3 114 116
38 C 594
60 S 604 8 117 993
27 B 605 1 160 717
34 S 606 5 108 577
33 C 595
19 B 608 2 154 332
5 S 609 1 138 730
48 S 610 8 169 962
22 B 611 0 117 70
49 C 229
19 B 613 8 147 317
38 C 416
26 C 578
59 S 616 9 125 97
32 S 617 5 129 919
62 C 180
41 B 619 8 197 563
6 B 620 7 131 113
63 B 621 1 181 953
6 S 622 7 161 98
17 S 623 5 121 606
19 C 600
13 C 249
23 C 188
18 C 164
36 S 628 5 112 70
