tests/64_threads/sample_15.in
64
o
50 B 101 1 145 46
53 S 103 2 192 154
16 S 104 7 117 800
63 B 105 4 143 660
50 S 107 6 197 668
29 S 108 9 179 238
37 S 109 1 162 321
1 B 110 4 117 86
29 S 111 0 172 431
9 S 114 9 181 926
34 B 115 1 116 269
23 B 116 0 198 769
17 S 117 1 120 171
31 B 118 6 159 30
46 B 119 6 179 271
38 B 120 9 136 848
49 S 121 3 162 557
11 S 122 3 198 945
52 B 124 3 172 220
62 S 125 6 107 428
6 S 126 0 106 216
10 S 127 5 155 361
30 B 128 6 197 86
56 B 130 4 136 653
40 S 131 1 192 431
30 S 132 0 130 511
49 B 134 3 173 347
0 B 135 2 173 187
60 B 136 4 143 480
49 C 121
2 S 139 9 194 427
25 S 140 9 193 140
49 B 141 1 157 585
20 S 142 9 127 717
57 B 143 9 116 198
48 B 144 4 165 957
24 S 146 2 139 139
34 C 115
3 B 148 5 145 381
37 S 149 5 126 260
0 C 135
9 S 151 2 153 427
31 S 153 4 143 525
47 S 154 5 100 87
11 C 122
26 B 156 5 113 947
22 B 157 1 103 301
37 S 158 2 115 673
55 S 159 5 144 851
28 S 160 2 125 118
14 B 161 3 191 435
36 S 163 5 198 395
62 S 164 6 176 239
25 B 165 5 122 624
51 S 166 2 101 382
29 C 111
7 B 168 7 137 972
1 C 110
44 B 171 2 186 454
52 C 124
36 C 163
53 C 103
59 B 177 7 181 86
9 S 178 2 158 958
37 B 179 3 168 847
28 B 180 1 116 887
53 S 181 9 131 385
25 B 182 9 160 510
41 S 183 8 195 390
62 B 184 4 133 685
17 S 185 2 171 735
7 B 186 9 173 670
25 C 182
55 C 159
59 B 189 8 151 538
30 S 190 6 122 529
6 S 191 8 138 111
11 S 192 4 139 989
56 C 130
38 B 194 3 105 756
29 S 196 2 171 542
13 S 197 9 107 922
63 S 198 0 138 620
61 S 199 0 101 634
12 S 200 6 148 122
16 B 201 2 148 382
7 S 203 1 144 200
14 S 204 6 110 256
32 S 205 1 159 598
46 S 206 8 152 886
52 S 207 7 136 560
51 S 208 0 134 279
37 C 109
17 S 210 6 169 785
11 S 211 4 193 874
6 S 212 5 198 417
42 B 213 9 176 520
47 B 214 1 106 789
53 B 215 4 163 231
1 C 110
48 C 144
13 S 218 3 110 628
49 S 219 7 117 792
42 C 213
54 B 221 7 164 534
58 B 223 4 126 966
23 B 224 2 106 137
22 B 225 3 184 64
63 C 105
25 B 227 8 125 538
47 S 228 5 173 906
1 S 229 9 134 868
57 C 143
30 C 132
52 B 233 2 109 836
57 B 234 9 185 644
47 S 235 3 100 682
50 S 236 3 185 285
49 S 237 7 178 525
39 B 238 1 163 999
41 S 239 9 138 276
61 B 240 2 134 673
42 S 241 1 110 21
32 B 242 2 147 434
40 S 243 3 145 116
33 B 244 8 172 558
62 C 184
15 B 246 1 128 53
54 C 221
46 B 248 9 136 301
47 B 249 8 144 710
61 B 250 3 197 895
23 B 251 4 154 490
11 S 252 6 110 328
63 S 253 9 199 825
46 S 254 4 143 95
46 C 119
31 S 256 3 180 44
63 C 105
16 B 258 6 139 157
25 S 259 3 143 230
60 B 260 1 182 293
30 S 262 4 157 732
6 S 263 4 141 965
41 S 264 5 199 744
57 B 265 0 140 806
2 B 266 6 154 626
40 B 267 1 181 59
38 B 268 2 164 77
23 S 270 9 100 377
18 B 272 0 133 290
10 S 273 9 195 41
25 B 274 1 137 729
3 S 275 8 166 219
5 S 276 1 113 337
23 C 224
47 S 278 0 142 606
49 C 141
44 B 280 1 141 156
61 S 281 9 171 562
12 C 200
50 C 107
2 S 285 6 175 606
44 C 280
35 B 287 5 191 810
26 C 156
26 S 289 5 153 436
37 B 290 3 137 431
5 B 291 4 189 699
55 C 159
49 C 141
22 S 294 0 193 935
33 C 244
0 B 296 5 127 818
24 B 297 7 194 652
42 C 241
17 S 299 2 127 270
26 C 156
37 C 179
8 B 302 4 120 468
27 B 303 3 116 359
17 B 304 2 115 272
60 B 305 7 114 816
35 S 306 0 154 811
4 S 307 5 137 797
32 S 308 8 102 808
18 S 309 7 147 32
28 C 180
51 C 208
19 B 312 6 107 812
38 S 313 3 148 550
48 B 314 2 188 832
43 S 315 7 195 301
31 S 316 8 189 549
19 C 312
62 B 318 4 192 850
55 C 159
4 C 307
20 C 142
23 B 322 0 110 285
15 C 246
62 B 324 3 174 734
61 C 281
18 S 326 5 165 261
59 B 327 8 140 394
29 S 328 7 134 626
0 C 135
48 B 330 5 118 791
30 C 262
48 C 144
9 S 333 4 150 971
30 B 334 9 129 971
42 S 335 1 117 454
41 B 336 8 120 361
40 B 337 9 122 413
19 B 338 0 142 618
28 B 339 8 152 874
11 C 211
12 S 341 7 125 440
15 C 246
7 B 343 1 146 641
11 C 211
34 S 345 7 179 203
24 S 346 3 173 966
12 C 200
23 C 224
60 B 349 1 127 620
19 B 350 8 110 871
17 S 351 9 113 191
4 B 352 5 155 470
18 C 326
32 B 354 7 104 39
42 B 355 4 126 757
56 S 356 1 185 877
37 C 149
33 S 358 8 150 321
40 C 267
11 B 360 9 144 533
30 C 190
20 C 142
14 B 363 0 147 869
31 C 256
53 S 365 7 192 530
56 S 366 9 104 311
51 B 367 5 155 722
34 S 368 7 122 346
5 B 369 9 188 488
49 B 370 8 192 553
41 S 371 6 131 563
3 C 148
47 S 373 3 165 629
53 S 374 8 134 928
62 S 375 6 111 615
11 B 376 5 199 180
13 C 218
34 B 378 9 184 143
4 C 352
58 S 380 4 140 177
6 S 381 6 137 49
19 C 338
50 C 107
56 B 384 5 110 590
61 C 199
1 S 386 2 100 49
34 C 378
21 S 388 4 110 814
3 C 275
39 B 390 2 196 887
29 S 391 2 105 903
17 B 392 9 152 401
40 S 393 0 101 887
54 S 394 1 137 134
2 C 139
60 B 396 5 142 798
34 C 378
28 B 398 7 171 458
29 C 391
48 B 400 5 146 74
63 C 198
44 S 402 4 189 659
9 S 403 9 179 337
52 C 124
63 C 198
33 S 406 4 189 794
38 C 120
39 S 408 1 112 100
33 S 409 1 186 633
31 C 256
47 S 411 1 106 91
14 S 412 1 109 102
16 S 413 8 172 216
24 B 414 7 197 489
10 C 127
26 B 416 5 138 521
34 S 417 2 162 701
55 C 159
18 S 419 8 151 633
28 B 420 9 169 586
28 B 421 9 146 438
17 C 304
47 S 423 9 126 248
29 C 391
16 B 425 4 145 35
44 S 426 1 104 758
6 B 427 7 176 875
11 S 428 0 105 320
6 S 429 6 194 254
59 C 327
41 B 431 3 118 346
44 B 432 3 117 382
22 C 157
63 C 198
58 C 380
7 B 436 0 165 205
3 C 148
3 S 438 6 112 235
14 B 439 9 178 222
22 C 157
19 C 350
31 S 442 3 166 165
62 C 318
26 S 444 4 107 780
14 S 445 7 149 863
38 C 120
16 B 447 6 146 157
44 B 448 1 129 384
49 S 449 2 181 167
63 S 450 3 159 320
3 C 275
27 C 303
52 B 453 1 174 952
13 C 197
39 B 455 3 164 423
58 C 380
62 S 457 1 116 324
18 S 458 2 126 392
47 S 459 9 133 871
17 B 460 3 176 724
2 B 461 1 166 119
12 S 462 9 188 722
20 C 142
39 S 464 3 117 593
39 B 465 2 103 466
29 C 328
18 C 458
15 B 468 8 160 182
15 B 469 5 169 164
25 C 140
59 B 471 9 189 515
24 B 472 1 190 305
31 S 473 7 198 419
58 B 474 2 149 323
18 B 476 9 196 43
58 S 477 7 119 63
4 C 307
23 S 479 6 114 763
12 C 462
47 C 278
23 B 482 3 169 98
11 C 252
26 S 484 4 161 26
29 S 485 3 126 793
13 C 218
44 S 487 1 167 328
49 C 219
42 S 489 1 179 941
31 S 490 6 195 498
14 S 491 4 198 296
50 B 492 5 156 868
8 S 493 0 129 16
34 S 494 9 196 855
56 S 495 9 152 597
20 B 496 5 185 165
55 B 497 2 193 703
15 C 469
63 S 499 7 166 68
63 S 500 6 190 169
61 C 281
14 S 502 2 172 422
3 C 148
63 C 450
29 S 505 7 183 225
61 S 506 7 186 414
53 S 507 7 126 913
44 S 508 2 100 594
11 S 509 8 193 881
50 C 107
45 B 511 1 120 155
15 B 512 2 147 191
52 B 513 3 142 284
25 C 259
24 B 515 6 135 840
28 B 516 2 177 447
40 C 131
29 S 518 3 100 572
19 S 519 3 159 58
14 B 520 0 184 887
33 C 409
50 C 236
54 S 523 9 176 625
33 B 524 3 127 214
21 S 525 1 166 726
13 B 526 5 167 335
39 S 527 3 117 799
43 C 315
24 C 297
5 C 276
3 C 438
5 C 291
32 B 533 7 195 314
47 C 214
13 C 197
18 B 536 2 142 473
17 B 537 0 191 759
14 C 502
20 C 142
8 B 540 8 105 417
21 S 541 2 181 970
33 S 542 7 182 353
51 B 543 7 112 89
3 B 544 3 171 170
48 C 330
26 C 444
41 B 547 6 198 456
39 B 548 5 148 933
45 S 549 0 111 350
32 S 550 5 139 384
33 B 551 1 109 864
10 B 552 3 193 456
28 C 160
25 S 554 8 178 232
36 B 555 2 141 338
18 B 556 6 149 281
37 S 557 9 166 759
19 C 350
7 S 559 1 135 71
63 C 198
26 C 416
16 S 562 8 149 384
0 C 296
54 C 523
38 S 565 1 129 78
48 S 566 4 114 851
27 B 567 5 111 82
35 S 568 4 181 62
8 B 569 2 101 367
35 B 570 6 174 236
59 S 571 9 133 803
36 C 555
53 B 573 4 102 875
31 C 473
57 B 575 9 105 491
23 B 576 9 120 743
34 S 577 9 160 549
8 B 578 8 178 324
53 C 181
10 C 552
2 S 581 4 168 621
20 S 582 4 147 299
19 B 583 1 173 159
9 C 333
6 C 429
56 C 384
53 B 587 9 104 838
52 B 588 0 175 747
20 C 582
38 B 590 1 194 564
25 C 554
33 S 592 2 155 243
37 B 593 1 139 160
28 S 594 6 193 673
45 B 595 7 133 454
5 C 276
10 C 273
33 S 598 3 140 994
60 S 599 3 105 435
59 S 600 2 143 670
39 C 527
61 C 281
18 S 603 1 169 651
36 B 604 2 108 582
6 B 605 6 109 322
7 B 606 5 170 710
24 C 515
59 B 608 7 106 362
42 S 609 7 141 50
47 B 610 3 118 808
49 S 611 5 124 344
11 B 612 5 127 374
8 B 613 3 196 256
34 C 115
61 B 615 6 128 756
18 B 616 6 131 855
32 C 354
41 C 336
45 C 549
22 S 620 3 188 631
6 C 605
49 S 622 5 128 724
36 S 623 5 200 650
1 B 624 6 152 504
1 S 625 8 174 425
33 B 626 0 184 791
